<?xml version="1.0" ?>
<!-- Generated using onshape-to-robot -->
<!-- Onshape document_id: 6b0deb9ebbbe1b46e45b974c / workspace_id: a3fb926f945c06933388de65 -->
<robot name="servobot">
  <!-- Link hipsubasm -->
  <link name="hipsubasm">
    <inertial>
      <origin xyz="-0.0596261 0.0982656 -0.0335213" rpy="0 0 0"/>
      <mass value="0.0661231"/>
      <inertia ixx="1.83846e-05" ixy="-5.65469e-07" ixz="9.10183e-08" iyy="2.20865e-05" iyz="8.52544e-08" izz="1.40437e-05"/>
    </inertial>
    <!-- Part hipjoint -->
    <visual>
      <origin xyz="-0.0451412 0.0984176 -0.0328385" rpy="1.5886e-15 1.77013e-16 -1.5708"/>
      <geometry>
        <mesh filename="package://servobot-urdf/description/meshes/hipjoint.stl"/>
      </geometry>
      <material name="hipjoint_material">
        <color rgba="0.231373 0.380392 0.705882 1"/>
      </material>
    </visual>
    <collision>
      <origin xyz="-0.0451412 0.0984176 -0.0328385" rpy="1.5886e-15 1.77013e-16 -1.5708"/>
      <geometry>
        <mesh filename="package://servobot-urdf/description/meshes/hipjoint.stl"/>
      </geometry>
    </collision>
    <!-- Part servo -->
    <visual>
      <origin xyz="-0.0369412 0.102168 -0.0336635" rpy="-1.5708 -1.5708 0"/>
      <geometry>
        <mesh filename="package://servobot-urdf/description/meshes/servo.stl"/>
      </geometry>
      <material name="servo_material">
        <color rgba="0.301961 0.301961 0.301961 1"/>
      </material>
    </visual>
    <collision>
      <origin xyz="-0.0369412 0.102168 -0.0336635" rpy="-1.5708 -1.5708 0"/>
      <geometry>
        <mesh filename="package://servobot-urdf/description/meshes/servo.stl"/>
      </geometry>
    </collision>
    <!-- Part servohornreplacement -->
    <visual>
      <origin xyz="-0.0551412 0.0811676 -0.0155485" rpy="-1.5708 -1.5708 0"/>
      <geometry>
        <mesh filename="package://servobot-urdf/description/meshes/servohornreplacement.stl"/>
      </geometry>
      <material name="servohornreplacement_material">
        <color rgba="0.615686 0.811765 0.929412 1"/>
      </material>
    </visual>
    <collision>
      <origin xyz="-0.0551412 0.0811676 -0.0155485" rpy="-1.5708 -1.5708 0"/>
      <geometry>
        <mesh filename="package://servobot-urdf/description/meshes/servohornreplacement.stl"/>
      </geometry>
    </collision>
  </link>
  <!-- Link mainbody -->
  <link name="mainbody">
    <inertial>
      <origin xyz="0.05515 -0.00881981 -0.081525" rpy="0 0 0"/>
      <mass value="0.493948"/>
      <inertia ixx="0.00138407" ixy="1.82959e-19" ixz="-1.0842e-18" iyy="0.00243138" iyz="-4.86875e-18" izz="0.00112985"/>
    </inertial>
    <!-- Part base -->
    <visual>
      <origin xyz="0.13515 -0.021 -0.156525" rpy="1.5708 -2.70816e-15 -3.14159"/>
      <geometry>
        <mesh filename="package://servobot-urdf/description/meshes/base.stl"/>
      </geometry>
      <material name="base_material">
        <color rgba="0.615686 0.811765 0.929412 1"/>
      </material>
    </visual>
    <collision>
      <origin xyz="0.13515 -0.021 -0.156525" rpy="1.5708 -2.70816e-15 -3.14159"/>
      <geometry>
        <mesh filename="package://servobot-urdf/description/meshes/base.stl"/>
      </geometry>
    </collision>
    <!-- Part servo_2 -->
    <visual>
      <origin xyz="0.01015 3.46945e-18 -0.1168" rpy="1.5708 2.70816e-15 1.67187e-15"/>
      <geometry>
        <mesh filename="package://servobot-urdf/description/meshes/servo.stl"/>
      </geometry>
      <material name="servo_2_material">
        <color rgba="0.301961 0.301961 0.301961 1"/>
      </material>
    </visual>
    <collision>
      <origin xyz="0.01015 3.46945e-18 -0.1168" rpy="1.5708 2.70816e-15 1.67187e-15"/>
      <geometry>
        <mesh filename="package://servobot-urdf/description/meshes/servo.stl"/>
      </geometry>
    </collision>
    <!-- Part servo_3 -->
    <visual>
      <origin xyz="0.01015 1.04083e-17 -0.04625" rpy="-1.5708 2.70816e-15 1.67187e-15"/>
      <geometry>
        <mesh filename="package://servobot-urdf/description/meshes/servo.stl"/>
      </geometry>
      <material name="servo_3_material">
        <color rgba="0.301961 0.301961 0.301961 1"/>
      </material>
    </visual>
    <collision>
      <origin xyz="0.01015 1.04083e-17 -0.04625" rpy="-1.5708 2.70816e-15 1.67187e-15"/>
      <geometry>
        <mesh filename="package://servobot-urdf/description/meshes/servo.stl"/>
      </geometry>
    </collision>
    <!-- Part servo_4 -->
    <visual>
      <origin xyz="0.10015 1.26635e-16 -0.04625" rpy="-1.5708 -2.70816e-15 -3.14159"/>
      <geometry>
        <mesh filename="package://servobot-urdf/description/meshes/servo.stl"/>
      </geometry>
      <material name="servo_4_material">
        <color rgba="0.301961 0.301961 0.301961 1"/>
      </material>
    </visual>
    <collision>
      <origin xyz="0.10015 1.26635e-16 -0.04625" rpy="-1.5708 -2.70816e-15 -3.14159"/>
      <geometry>
        <mesh filename="package://servobot-urdf/description/meshes/servo.stl"/>
      </geometry>
    </collision>
    <!-- Part servo_5 -->
    <visual>
      <origin xyz="0.10015 1.26635e-16 -0.1168" rpy="1.5708 -2.70816e-15 -3.14159"/>
      <geometry>
        <mesh filename="package://servobot-urdf/description/meshes/servo.stl"/>
      </geometry>
      <material name="servo_5_material">
        <color rgba="0.301961 0.301961 0.301961 1"/>
      </material>
    </visual>
    <collision>
      <origin xyz="0.10015 1.26635e-16 -0.1168" rpy="1.5708 -2.70816e-15 -3.14159"/>
      <geometry>
        <mesh filename="package://servobot-urdf/description/meshes/servo.stl"/>
      </geometry>
    </collision>
  </link>
  <!-- Link hipsubasm_2 -->
  <link name="hipsubasm_2">
    <inertial>
      <origin xyz="-0.00448487 -0.0179728 -0.0160981" rpy="0 0 0"/>
      <mass value="0.0661231"/>
      <inertia ixx="1.83846e-05" ixy="9.10183e-08" ixz="5.65469e-07" iyy="1.40437e-05" iyz="-8.52544e-08" izz="2.20865e-05"/>
    </inertial>
    <!-- Part hipjoint_2 -->
    <visual>
      <origin xyz="0.01 -0.01729 -0.01625" rpy="-1.5708 -1.5708 0"/>
      <geometry>
        <mesh filename="package://servobot-urdf/description/meshes/hipjoint.stl"/>
      </geometry>
      <material name="hipjoint_2_material">
        <color rgba="0.231373 0.380392 0.705882 1"/>
      </material>
    </visual>
    <collision>
      <origin xyz="0.01 -0.01729 -0.01625" rpy="-1.5708 -1.5708 0"/>
      <geometry>
        <mesh filename="package://servobot-urdf/description/meshes/hipjoint.stl"/>
      </geometry>
    </collision>
    <!-- Part servo_6 -->
    <visual>
      <origin xyz="0.0182 -0.018115 -0.02" rpy="3.14159 -3.54025e-16 1.5708"/>
      <geometry>
        <mesh filename="package://servobot-urdf/description/meshes/servo.stl"/>
      </geometry>
      <material name="servo_6_material">
        <color rgba="0.301961 0.301961 0.301961 1"/>
      </material>
    </visual>
    <collision>
      <origin xyz="0.0182 -0.018115 -0.02" rpy="3.14159 -3.54025e-16 1.5708"/>
      <geometry>
        <mesh filename="package://servobot-urdf/description/meshes/servo.stl"/>
      </geometry>
    </collision>
    <!-- Part servohornreplacement_2 -->
    <visual>
      <origin xyz="0 0 0.001" rpy="-3.14159 -3.54025e-16 1.5708"/>
      <geometry>
        <mesh filename="package://servobot-urdf/description/meshes/servohornreplacement.stl"/>
      </geometry>
      <material name="servohornreplacement_2_material">
        <color rgba="0.615686 0.811765 0.929412 1"/>
      </material>
    </visual>
    <collision>
      <origin xyz="0 0 0.001" rpy="-3.14159 -3.54025e-16 1.5708"/>
      <geometry>
        <mesh filename="package://servobot-urdf/description/meshes/servohornreplacement.stl"/>
      </geometry>
    </collision>
  </link>
  <!-- Link toplegasm -->
  <link name="toplegasm">
    <inertial>
      <origin xyz="-3.39929e-19 0.056 -0.00366855" rpy="0 0 0"/>
      <mass value="0.025684"/>
      <inertia ixx="3.39573e-05" ixy="1.34129e-20" ixz="-1.46243e-20" iyy="1.21137e-06" iyz="-3.4902e-20" izz="3.49136e-05"/>
    </inertial>
    <!-- Part servohornreplacement_3 -->
    <visual>
      <origin xyz="-1.38778e-17 -6.93889e-18 -0.0058" rpy="-3.3126e-31 7.78254e-33 -9.71387e-35"/>
      <geometry>
        <mesh filename="package://servobot-urdf/description/meshes/servohornreplacement.stl"/>
      </geometry>
      <material name="servohornreplacement_3_material">
        <color rgba="0.615686 0.811765 0.929412 1"/>
      </material>
    </visual>
    <collision>
      <origin xyz="-1.38778e-17 -6.93889e-18 -0.0058" rpy="-3.3126e-31 7.78254e-33 -9.71387e-35"/>
      <geometry>
        <mesh filename="package://servobot-urdf/description/meshes/servohornreplacement.stl"/>
      </geometry>
    </collision>
    <!-- Part toplegcover -->
    <visual>
      <origin xyz="-4.16334e-17 0.056 -0.0079" rpy="1.5708 9.34358e-17 4.12629e-16"/>
      <geometry>
        <mesh filename="package://servobot-urdf/description/meshes/toplegcover.stl"/>
      </geometry>
      <material name="toplegcover_material">
        <color rgba="0.615686 0.811765 0.929412 1"/>
      </material>
    </visual>
    <collision>
      <origin xyz="-4.16334e-17 0.056 -0.0079" rpy="1.5708 9.34358e-17 4.12629e-16"/>
      <geometry>
        <mesh filename="package://servobot-urdf/description/meshes/toplegcover.stl"/>
      </geometry>
    </collision>
    <!-- Part servohornreplacement_4 -->
    <visual>
      <origin xyz="-2.77556e-17 0.112 -0.0058" rpy="-2.498e-16 -1.09199e-15 -7.15585e-16"/>
      <geometry>
        <mesh filename="package://servobot-urdf/description/meshes/servohornreplacement.stl"/>
      </geometry>
      <material name="servohornreplacement_4_material">
        <color rgba="0.615686 0.811765 0.929412 1"/>
      </material>
    </visual>
    <collision>
      <origin xyz="-2.77556e-17 0.112 -0.0058" rpy="-2.498e-16 -1.09199e-15 -7.15585e-16"/>
      <geometry>
        <mesh filename="package://servobot-urdf/description/meshes/servohornreplacement.stl"/>
      </geometry>
    </collision>
    <!-- Part topleg -->
    <visual>
      <origin xyz="1.38778e-17 0.056 -0.0079" rpy="2.60209e-16 1.00784e-16 4.20046e-16"/>
      <geometry>
        <mesh filename="package://servobot-urdf/description/meshes/topleg.stl"/>
      </geometry>
      <material name="topleg_material">
        <color rgba="0.231373 0.380392 0.705882 1"/>
      </material>
    </visual>
    <collision>
      <origin xyz="1.38778e-17 0.056 -0.0079" rpy="2.60209e-16 1.00784e-16 4.20046e-16"/>
      <geometry>
        <mesh filename="package://servobot-urdf/description/meshes/topleg.stl"/>
      </geometry>
    </collision>
  </link>
  <!-- Link botlegasm -->
  <link name="botlegasm">
    <inertial>
      <origin xyz="0.0143552 3.49142e-12 -0.0172417" rpy="0 0 0"/>
      <mass value="0.0546456"/>
      <inertia ixx="1.09163e-05" ixy="7.88005e-16" ixz="-3.3093e-06" iyy="3.02885e-05" iyz="-3.17388e-15" izz="2.44221e-05"/>
    </inertial>
    <!-- Part servo_7 -->
    <visual>
      <origin xyz="0.01015 0 -0.04045" rpy="-1.5708 -6.05537e-32 -1.12454e-42"/>
      <geometry>
        <mesh filename="package://servobot-urdf/description/meshes/servo.stl"/>
      </geometry>
      <material name="servo_7_material">
        <color rgba="0.301961 0.301961 0.301961 1"/>
      </material>
    </visual>
    <collision>
      <origin xyz="0.01015 0 -0.04045" rpy="-1.5708 -6.05537e-32 -1.12454e-42"/>
      <geometry>
        <mesh filename="package://servobot-urdf/description/meshes/servo.stl"/>
      </geometry>
    </collision>
    <!-- Part botleg -->
    <visual>
      <origin xyz="0.0316745 -2.77556e-17 2.5e-05" rpy="1.5708 -3.874e-31 -1.5708"/>
      <geometry>
        <mesh filename="package://servobot-urdf/description/meshes/botleg.stl"/>
      </geometry>
      <material name="botleg_material">
        <color rgba="0.87451 0.447059 0.317647 1"/>
      </material>
    </visual>
    <collision>
      <origin xyz="0.0316745 -2.77556e-17 2.5e-05" rpy="1.5708 -3.874e-31 -1.5708"/>
      <geometry>
        <mesh filename="package://servobot-urdf/description/meshes/botleg.stl"/>
      </geometry>
    </collision>
  </link>
  <!-- Joint from toplegasm to botlegasm -->
  <joint name="BR_BotLeg" type="revolute">
    <origin xyz="-2.77556e-17 0.112 4.16334e-17" rpy="3.14159 -8.49659e-15 1.5708"/>
    <parent link="toplegasm"/>
    <child link="botlegasm"/>
    <axis xyz="0 0 1"/>
    <limit effort="10" velocity="10" lower="-3.141592653589793" upper="3.141592653589793"/>
  </joint>
  <!-- Joint from hipsubasm_2 to toplegasm -->
  <joint name="BR_TopLeg" type="revolute">
    <origin xyz="-0.02225 -0.028265 -0.02" rpy="3.14159 -1.5708 0"/>
    <parent link="hipsubasm_2"/>
    <child link="toplegasm"/>
    <axis xyz="0 0 1"/>
    <limit effort="10" velocity="10" lower="-1.5708" upper="1.5708"/>
  </joint>
  <!-- Joint from mainbody to hipsubasm_2 -->
  <joint name="BR_Hip" type="revolute">
    <origin xyz="0.1103 1.42247e-16 -0.16305" rpy="2.95937e-15 -2.70816e-15 -3.14159"/>
    <parent link="mainbody"/>
    <child link="hipsubasm_2"/>
    <axis xyz="0 0 1"/>
    <limit effort="10" velocity="10" lower="-0.785398" upper="0.785398"/>
  </joint>
  <!-- Link mirroredhipsubasm -->
  <link name="mirroredhipsubasm">
    <inertial>
      <origin xyz="-0.00448487 0.0179728 -0.0160981" rpy="0 0 0"/>
      <mass value="0.0661231"/>
      <inertia ixx="1.83846e-05" ixy="-9.10183e-08" ixz="5.65469e-07" iyy="1.40437e-05" iyz="8.52544e-08" izz="2.20865e-05"/>
    </inertial>
    <!-- Part servo_8 -->
    <visual>
      <origin xyz="0.0182 0.018115 -0.02" rpy="1.86073e-15 -1.29994e-16 -1.5708"/>
      <geometry>
        <mesh filename="package://servobot-urdf/description/meshes/servo.stl"/>
      </geometry>
      <material name="servo_8_material">
        <color rgba="0.301961 0.301961 0.301961 1"/>
      </material>
    </visual>
    <collision>
      <origin xyz="0.0182 0.018115 -0.02" rpy="1.86073e-15 -1.29994e-16 -1.5708"/>
      <geometry>
        <mesh filename="package://servobot-urdf/description/meshes/servo.stl"/>
      </geometry>
    </collision>
    <!-- Part mirrorhipjoint -->
    <visual>
      <origin xyz="0.01 0.01729 -0.02375" rpy="1.5708 1.5708 0"/>
      <geometry>
        <mesh filename="package://servobot-urdf/description/meshes/mirrorhipjoint.stl"/>
      </geometry>
      <material name="mirrorhipjoint_material">
        <color rgba="0.231373 0.380392 0.705882 1"/>
      </material>
    </visual>
    <collision>
      <origin xyz="0.01 0.01729 -0.02375" rpy="1.5708 1.5708 0"/>
      <geometry>
        <mesh filename="package://servobot-urdf/description/meshes/mirrorhipjoint.stl"/>
      </geometry>
    </collision>
    <!-- Part servohornreplacement_5 -->
    <visual>
      <origin xyz="-6.93889e-18 -8.67362e-18 0.001" rpy="-3.14159 1.9286e-15 3.14159"/>
      <geometry>
        <mesh filename="package://servobot-urdf/description/meshes/servohornreplacement.stl"/>
      </geometry>
      <material name="servohornreplacement_5_material">
        <color rgba="0.615686 0.811765 0.929412 1"/>
      </material>
    </visual>
    <collision>
      <origin xyz="-6.93889e-18 -8.67362e-18 0.001" rpy="-3.14159 1.9286e-15 3.14159"/>
      <geometry>
        <mesh filename="package://servobot-urdf/description/meshes/servohornreplacement.stl"/>
      </geometry>
    </collision>
  </link>
  <!-- Link toplegasm_2 -->
  <link name="toplegasm_2">
    <inertial>
      <origin xyz="3.69975e-16 0.056 -0.00366855" rpy="0 0 0"/>
      <mass value="0.025684"/>
      <inertia ixx="3.39573e-05" ixy="1.88122e-20" ixz="3.13174e-21" iyy="1.21137e-06" iyz="3.74091e-22" izz="3.49136e-05"/>
    </inertial>
    <!-- Part servohornreplacement_6 -->
    <visual>
      <origin xyz="0 0 -0.0058" rpy="1.54601e-32 -7.05158e-33 -4.93038e-32"/>
      <geometry>
        <mesh filename="package://servobot-urdf/description/meshes/servohornreplacement.stl"/>
      </geometry>
      <material name="servohornreplacement_6_material">
        <color rgba="0.615686 0.811765 0.929412 1"/>
      </material>
    </visual>
    <collision>
      <origin xyz="0 0 -0.0058" rpy="1.54601e-32 -7.05158e-33 -4.93038e-32"/>
      <geometry>
        <mesh filename="package://servobot-urdf/description/meshes/servohornreplacement.stl"/>
      </geometry>
    </collision>
    <!-- Part toplegcover_2 -->
    <visual>
      <origin xyz="3.19189e-16 0.056 -0.0079" rpy="1.5708 -1.249e-16 7.77156e-16"/>
      <geometry>
        <mesh filename="package://servobot-urdf/description/meshes/toplegcover.stl"/>
      </geometry>
      <material name="toplegcover_2_material">
        <color rgba="0.615686 0.811765 0.929412 1"/>
      </material>
    </visual>
    <collision>
      <origin xyz="3.19189e-16 0.056 -0.0079" rpy="1.5708 -1.249e-16 7.77156e-16"/>
      <geometry>
        <mesh filename="package://servobot-urdf/description/meshes/toplegcover.stl"/>
      </geometry>
    </collision>
    <!-- Part servohornreplacement_7 -->
    <visual>
      <origin xyz="7.35523e-16 0.112 -0.0058" rpy="4.996e-16 6.93889e-17 4.71845e-16"/>
      <geometry>
        <mesh filename="package://servobot-urdf/description/meshes/servohornreplacement.stl"/>
      </geometry>
      <material name="servohornreplacement_7_material">
        <color rgba="0.615686 0.811765 0.929412 1"/>
      </material>
    </visual>
    <collision>
      <origin xyz="7.35523e-16 0.112 -0.0058" rpy="4.996e-16 6.93889e-17 4.71845e-16"/>
      <geometry>
        <mesh filename="package://servobot-urdf/description/meshes/servohornreplacement.stl"/>
      </geometry>
    </collision>
    <!-- Part topleg_2 -->
    <visual>
      <origin xyz="3.747e-16 0.056 -0.0079" rpy="-5.96745e-16 1.70697e-15 8.04912e-16"/>
      <geometry>
        <mesh filename="package://servobot-urdf/description/meshes/topleg.stl"/>
      </geometry>
      <material name="topleg_2_material">
        <color rgba="0.231373 0.380392 0.705882 1"/>
      </material>
    </visual>
    <collision>
      <origin xyz="3.747e-16 0.056 -0.0079" rpy="-5.96745e-16 1.70697e-15 8.04912e-16"/>
      <geometry>
        <mesh filename="package://servobot-urdf/description/meshes/topleg.stl"/>
      </geometry>
    </collision>
  </link>
  <!-- Link botlegasm_2 -->
  <link name="botlegasm_2">
    <inertial>
      <origin xyz="0.0143552 3.49141e-12 -0.0172417" rpy="0 0 0"/>
      <mass value="0.0546456"/>
      <inertia ixx="1.09163e-05" ixy="7.88022e-16" ixz="-3.3093e-06" iyy="3.02885e-05" iyz="-3.17388e-15" izz="2.44221e-05"/>
    </inertial>
    <!-- Part servo_9 -->
    <visual>
      <origin xyz="0.01015 -1.38778e-17 -0.04045" rpy="-1.5708 -1.02932e-32 1.20839e-25"/>
      <geometry>
        <mesh filename="package://servobot-urdf/description/meshes/servo.stl"/>
      </geometry>
      <material name="servo_9_material">
        <color rgba="0.301961 0.301961 0.301961 1"/>
      </material>
    </visual>
    <collision>
      <origin xyz="0.01015 -1.38778e-17 -0.04045" rpy="-1.5708 -1.02932e-32 1.20839e-25"/>
      <geometry>
        <mesh filename="package://servobot-urdf/description/meshes/servo.stl"/>
      </geometry>
    </collision>
    <!-- Part botleg_2 -->
    <visual>
      <origin xyz="0.0316745 -1.38778e-17 2.5e-05" rpy="1.5708 -6.93889e-18 -1.5708"/>
      <geometry>
        <mesh filename="package://servobot-urdf/description/meshes/botleg.stl"/>
      </geometry>
      <material name="botleg_2_material">
        <color rgba="0.87451 0.447059 0.317647 1"/>
      </material>
    </visual>
    <collision>
      <origin xyz="0.0316745 -1.38778e-17 2.5e-05" rpy="1.5708 -6.93889e-18 -1.5708"/>
      <geometry>
        <mesh filename="package://servobot-urdf/description/meshes/botleg.stl"/>
      </geometry>
    </collision>
  </link>
  <!-- Joint from toplegasm_2 to botlegasm_2 -->
  <joint name="BL_BotLeg" type="revolute">
    <origin xyz="7.35523e-16 0.112 -4.16334e-17" rpy="-3.14159 2.22045e-16 1.5708"/>
    <parent link="toplegasm_2"/>
    <child link="botlegasm_2"/>
    <axis xyz="0 0 1"/>
    <limit effort="10" velocity="10" lower="-3.141592653589793" upper="3.141592653589793"/>
  </joint>
  <!-- Joint from mirroredhipsubasm to toplegasm_2 -->
  <joint name="BL_TopLeg" type="revolute">
    <origin xyz="-0.02225 0.028265 -0.02" rpy="2.55043e-16 1.5708 0"/>
    <parent link="mirroredhipsubasm"/>
    <child link="toplegasm_2"/>
    <axis xyz="0 0 1"/>
    <limit effort="10" velocity="10" lower="-1.5708" upper="1.5708"/>
  </joint>
  <!-- Joint from mainbody to mirroredhipsubasm -->
  <joint name="BL_Hip" type="revolute">
    <origin xyz="-2.77556e-16 -8.67362e-18 -0.16305" rpy="-2.95937e-15 4.82972e-15 1.76636e-15"/>
    <parent link="mainbody"/>
    <child link="mirroredhipsubasm"/>
    <axis xyz="0 0 1"/>
    <limit effort="10" velocity="10" lower="-0.785398" upper="0.785398"/>
  </joint>
  <!-- Link mirroredhipsubasm_2 -->
  <link name="mirroredhipsubasm_2">
    <inertial>
      <origin xyz="-0.00448487 0.0179728 -0.0160981" rpy="0 0 0"/>
      <mass value="0.0661231"/>
      <inertia ixx="1.83846e-05" ixy="-9.10183e-08" ixz="5.65469e-07" iyy="1.40437e-05" iyz="8.52544e-08" izz="2.20865e-05"/>
    </inertial>
    <!-- Part servo_10 -->
    <visual>
      <origin xyz="0.0182 0.018115 -0.02" rpy="-2.6083e-16 -1.77013e-16 -1.5708"/>
      <geometry>
        <mesh filename="package://servobot-urdf/description/meshes/servo.stl"/>
      </geometry>
      <material name="servo_10_material">
        <color rgba="0.301961 0.301961 0.301961 1"/>
      </material>
    </visual>
    <collision>
      <origin xyz="0.0182 0.018115 -0.02" rpy="-2.6083e-16 -1.77013e-16 -1.5708"/>
      <geometry>
        <mesh filename="package://servobot-urdf/description/meshes/servo.stl"/>
      </geometry>
    </collision>
    <!-- Part mirrorhipjoint_2 -->
    <visual>
      <origin xyz="0.01 0.01729 -0.02375" rpy="1.5708 1.5708 0"/>
      <geometry>
        <mesh filename="package://servobot-urdf/description/meshes/mirrorhipjoint.stl"/>
      </geometry>
      <material name="mirrorhipjoint_2_material">
        <color rgba="0.231373 0.380392 0.705882 1"/>
      </material>
    </visual>
    <collision>
      <origin xyz="0.01 0.01729 -0.02375" rpy="1.5708 1.5708 0"/>
      <geometry>
        <mesh filename="package://servobot-urdf/description/meshes/mirrorhipjoint.stl"/>
      </geometry>
    </collision>
    <!-- Part servohornreplacement_8 -->
    <visual>
      <origin xyz="0 -5.20417e-18 0.001" rpy="-3.14159 -1.57797e-16 3.14159"/>
      <geometry>
        <mesh filename="package://servobot-urdf/description/meshes/servohornreplacement.stl"/>
      </geometry>
      <material name="servohornreplacement_8_material">
        <color rgba="0.615686 0.811765 0.929412 1"/>
      </material>
    </visual>
    <collision>
      <origin xyz="0 -5.20417e-18 0.001" rpy="-3.14159 -1.57797e-16 3.14159"/>
      <geometry>
        <mesh filename="package://servobot-urdf/description/meshes/servohornreplacement.stl"/>
      </geometry>
    </collision>
  </link>
  <!-- Link toplegasm_3 -->
  <link name="toplegasm_3">
    <inertial>
      <origin xyz="-3.98998e-17 0.056 -0.00366855" rpy="0 0 0"/>
      <mass value="0.025684"/>
      <inertia ixx="3.39573e-05" ixy="7.82512e-22" ixz="-1.44544e-19" iyy="1.21137e-06" iyz="-4.63178e-21" izz="3.49136e-05"/>
    </inertial>
    <!-- Part servohornreplacement_9 -->
    <visual>
      <origin xyz="0 0 -0.0058" rpy="-5.57108e-31 1.2151e-31 -1.11775e-33"/>
      <geometry>
        <mesh filename="package://servobot-urdf/description/meshes/servohornreplacement.stl"/>
      </geometry>
      <material name="servohornreplacement_9_material">
        <color rgba="0.615686 0.811765 0.929412 1"/>
      </material>
    </visual>
    <collision>
      <origin xyz="0 0 -0.0058" rpy="-5.57108e-31 1.2151e-31 -1.11775e-33"/>
      <geometry>
        <mesh filename="package://servobot-urdf/description/meshes/servohornreplacement.stl"/>
      </geometry>
    </collision>
    <!-- Part toplegcover_3 -->
    <visual>
      <origin xyz="-8.32667e-17 0.056 -0.0079" rpy="1.5708 4.55826e-15 -3.25626e-18"/>
      <geometry>
        <mesh filename="package://servobot-urdf/description/meshes/toplegcover.stl"/>
      </geometry>
      <material name="toplegcover_3_material">
        <color rgba="0.615686 0.811765 0.929412 1"/>
      </material>
    </visual>
    <collision>
      <origin xyz="-8.32667e-17 0.056 -0.0079" rpy="1.5708 4.55826e-15 -3.25626e-18"/>
      <geometry>
        <mesh filename="package://servobot-urdf/description/meshes/toplegcover.stl"/>
      </geometry>
    </collision>
    <!-- Part servohornreplacement_10 -->
    <visual>
      <origin xyz="-8.32667e-17 0.112 -0.0058" rpy="8.50893e-15 4.67526e-15 5.22549e-17"/>
      <geometry>
        <mesh filename="package://servobot-urdf/description/meshes/servohornreplacement.stl"/>
      </geometry>
      <material name="servohornreplacement_10_material">
        <color rgba="0.615686 0.811765 0.929412 1"/>
      </material>
    </visual>
    <collision>
      <origin xyz="-8.32667e-17 0.112 -0.0058" rpy="8.50893e-15 4.67526e-15 5.22549e-17"/>
      <geometry>
        <mesh filename="package://servobot-urdf/description/meshes/servohornreplacement.stl"/>
      </geometry>
    </collision>
    <!-- Part topleg_3 -->
    <visual>
      <origin xyz="-2.77556e-17 0.056 -0.0079" rpy="4.60323e-15 4.55826e-15 -7.28073e-33"/>
      <geometry>
        <mesh filename="package://servobot-urdf/description/meshes/topleg.stl"/>
      </geometry>
      <material name="topleg_3_material">
        <color rgba="0.231373 0.380392 0.705882 1"/>
      </material>
    </visual>
    <collision>
      <origin xyz="-2.77556e-17 0.056 -0.0079" rpy="4.60323e-15 4.55826e-15 -7.28073e-33"/>
      <geometry>
        <mesh filename="package://servobot-urdf/description/meshes/topleg.stl"/>
      </geometry>
    </collision>
  </link>
  <!-- Link botlegasm_3 -->
  <link name="botlegasm_3">
    <inertial>
      <origin xyz="0.0143552 3.49141e-12 -0.0172417" rpy="0 0 0"/>
      <mass value="0.0546456"/>
      <inertia ixx="1.09163e-05" ixy="7.88109e-16" ixz="-3.3093e-06" iyy="3.02885e-05" iyz="-3.17387e-15" izz="2.44221e-05"/>
    </inertial>
    <!-- Part servo_11 -->
    <visual>
      <origin xyz="0.01015 -1.38778e-17 -0.04045" rpy="-1.5708 3.77656e-33 9.86076e-32"/>
      <geometry>
        <mesh filename="package://servobot-urdf/description/meshes/servo.stl"/>
      </geometry>
      <material name="servo_11_material">
        <color rgba="0.301961 0.301961 0.301961 1"/>
      </material>
    </visual>
    <collision>
      <origin xyz="0.01015 -1.38778e-17 -0.04045" rpy="-1.5708 3.77656e-33 9.86076e-32"/>
      <geometry>
        <mesh filename="package://servobot-urdf/description/meshes/servo.stl"/>
      </geometry>
    </collision>
    <!-- Part botleg_3 -->
    <visual>
      <origin xyz="0.0316745 -4.16334e-17 2.5e-05" rpy="1.5708 6.96168e-32 -1.5708"/>
      <geometry>
        <mesh filename="package://servobot-urdf/description/meshes/botleg.stl"/>
      </geometry>
      <material name="botleg_3_material">
        <color rgba="0.87451 0.447059 0.317647 1"/>
      </material>
    </visual>
    <collision>
      <origin xyz="0.0316745 -4.16334e-17 2.5e-05" rpy="1.5708 6.96168e-32 -1.5708"/>
      <geometry>
        <mesh filename="package://servobot-urdf/description/meshes/botleg.stl"/>
      </geometry>
    </collision>
  </link>
  <!-- Joint from toplegasm_3 to botlegasm_3 -->
  <joint name="FR_BotLeg" type="revolute">
    <origin xyz="-8.32667e-17 0.112 4.57967e-16" rpy="-3.14159 -8.68483e-15 1.5708"/>
    <parent link="toplegasm_3"/>
    <child link="botlegasm_3"/>
    <axis xyz="0 0 1"/>
    <limit effort="10" velocity="10" lower="-3.141592653589793" upper="3.141592653589793"/>
  </joint>
  <!-- Joint from mirroredhipsubasm_2 to toplegasm_3 -->
  <joint name="FR_TopLeg" type="revolute">
    <origin xyz="-0.02225 0.028265 -0.02" rpy="-1.66533e-16 1.5708 0"/>
    <parent link="mirroredhipsubasm_2"/>
    <child link="toplegasm_3"/>
    <axis xyz="0 0 1"/>
    <limit effort="10" velocity="10" lower="-1.5708" upper="1.5708"/>
  </joint>
  <!-- Joint from mainbody to mirroredhipsubasm_2 -->
  <joint name="FR_Hip" type="revolute">
    <origin xyz="0.1103 1.49186e-16 -3.33067e-16" rpy="-3.14159 -2.71489e-15 -3.14159"/>
    <parent link="mainbody"/>
    <child link="mirroredhipsubasm_2"/>
    <axis xyz="0 0 1"/>
    <limit effort="10" velocity="10" lower="-0.785398" upper="0.785398"/>
  </joint>
  <!-- Joint from hipsubasm to mainbody -->
  <joint name="FL_Hip" type="revolute">
    <origin xyz="-0.0551412 0.0821676 -0.0155485" rpy="-1.5708 -1.5886e-15 2.70816e-15"/>
    <parent link="hipsubasm"/>
    <child link="mainbody"/>
    <axis xyz="0 0 1"/>
    <limit effort="10" velocity="10" lower="-0.785398" upper="0.785398"/>
  </joint>
  <!-- Link toplegasm_4 -->
  <link name="toplegasm_4">
    <inertial>
      <origin xyz="3.44148e-17 0.056 -0.00366855" rpy="0 0 0"/>
      <mass value="0.025684"/>
      <inertia ixx="3.39573e-05" ixy="-7.25965e-21" ixz="9.52378e-20" iyy="1.21137e-06" iyz="1.89896e-20" izz="3.49136e-05"/>
    </inertial>
    <!-- Part servohornreplacement_11 -->
    <visual>
      <origin xyz="0 -6.93889e-18 -0.0058" rpy="-1.6298e-30 -2.01168e-32 -8.93631e-31"/>
      <geometry>
        <mesh filename="package://servobot-urdf/description/meshes/servohornreplacement.stl"/>
      </geometry>
      <material name="servohornreplacement_11_material">
        <color rgba="0.615686 0.811765 0.929412 1"/>
      </material>
    </visual>
    <collision>
      <origin xyz="0 -6.93889e-18 -0.0058" rpy="-1.6298e-30 -2.01168e-32 -8.93631e-31"/>
      <geometry>
        <mesh filename="package://servobot-urdf/description/meshes/servohornreplacement.stl"/>
      </geometry>
    </collision>
    <!-- Part toplegcover_4 -->
    <visual>
      <origin xyz="-1.38778e-17 0.056 -0.0079" rpy="1.5708 -1.67227e-15 -2.77556e-16"/>
      <geometry>
        <mesh filename="package://servobot-urdf/description/meshes/toplegcover.stl"/>
      </geometry>
      <material name="toplegcover_4_material">
        <color rgba="0.615686 0.811765 0.929412 1"/>
      </material>
    </visual>
    <collision>
      <origin xyz="-1.38778e-17 0.056 -0.0079" rpy="1.5708 -1.67227e-15 -2.77556e-16"/>
      <geometry>
        <mesh filename="package://servobot-urdf/description/meshes/toplegcover.stl"/>
      </geometry>
    </collision>
    <!-- Part servohornreplacement_12 -->
    <visual>
      <origin xyz="2.77556e-17 0.112 -0.0058" rpy="-3.8719e-15 -1.51094e-15 -1.58207e-15"/>
      <geometry>
        <mesh filename="package://servobot-urdf/description/meshes/servohornreplacement.stl"/>
      </geometry>
      <material name="servohornreplacement_12_material">
        <color rgba="0.615686 0.811765 0.929412 1"/>
      </material>
    </visual>
    <collision>
      <origin xyz="2.77556e-17 0.112 -0.0058" rpy="-3.8719e-15 -1.51094e-15 -1.58207e-15"/>
      <geometry>
        <mesh filename="package://servobot-urdf/description/meshes/servohornreplacement.stl"/>
      </geometry>
    </collision>
    <!-- Part topleg_4 -->
    <visual>
      <origin xyz="4.16334e-17 0.056 -0.0079" rpy="-1.215e-14 -1.68615e-15 -2.22045e-16"/>
      <geometry>
        <mesh filename="package://servobot-urdf/description/meshes/topleg.stl"/>
      </geometry>
      <material name="topleg_4_material">
        <color rgba="0.231373 0.380392 0.705882 1"/>
      </material>
    </visual>
    <collision>
      <origin xyz="4.16334e-17 0.056 -0.0079" rpy="-1.215e-14 -1.68615e-15 -2.22045e-16"/>
      <geometry>
        <mesh filename="package://servobot-urdf/description/meshes/topleg.stl"/>
      </geometry>
    </collision>
  </link>
  <!-- Link botlegasm_4 -->
  <link name="botlegasm_4">
    <inertial>
      <origin xyz="0.0143552 3.49141e-12 -0.0172417" rpy="0 0 0"/>
      <mass value="0.0546456"/>
      <inertia ixx="1.09163e-05" ixy="7.88027e-16" ixz="-3.3093e-06" iyy="3.02885e-05" iyz="-3.17386e-15" izz="2.44221e-05"/>
    </inertial>
    <!-- Part servo_12 -->
    <visual>
      <origin xyz="0.01015 0 -0.04045" rpy="-1.5708 1.3428e-33 -1.10934e-31"/>
      <geometry>
        <mesh filename="package://servobot-urdf/description/meshes/servo.stl"/>
      </geometry>
      <material name="servo_12_material">
        <color rgba="0.301961 0.301961 0.301961 1"/>
      </material>
    </visual>
    <collision>
      <origin xyz="0.01015 0 -0.04045" rpy="-1.5708 1.3428e-33 -1.10934e-31"/>
      <geometry>
        <mesh filename="package://servobot-urdf/description/meshes/servo.stl"/>
      </geometry>
    </collision>
    <!-- Part botleg_4 -->
    <visual>
      <origin xyz="0.0316745 -6.93889e-17 2.5e-05" rpy="1.5708 -4.56518e-31 -1.5708"/>
      <geometry>
        <mesh filename="package://servobot-urdf/description/meshes/botleg.stl"/>
      </geometry>
      <material name="botleg_4_material">
        <color rgba="0.87451 0.447059 0.317647 1"/>
      </material>
    </visual>
    <collision>
      <origin xyz="0.0316745 -6.93889e-17 2.5e-05" rpy="1.5708 -4.56518e-31 -1.5708"/>
      <geometry>
        <mesh filename="package://servobot-urdf/description/meshes/botleg.stl"/>
      </geometry>
    </collision>
  </link>
  <!-- Joint from toplegasm_4 to botlegasm_4 -->
  <joint name="FL_BotLeg" type="revolute">
    <origin xyz="4.16334e-17 0.112 -1.34615e-15" rpy="3.14159 1.42113e-14 1.5708"/>
    <parent link="toplegasm_4"/>
    <child link="botlegasm_4"/>
    <axis xyz="0 0 1"/>
    <limit effort="10" velocity="10" lower="-3.141592653589793" upper="3.141592653589793"/>
  </joint>
  <!-- Joint from hipsubasm to toplegasm_4 -->
  <joint name="FL_TopLeg" type="revolute">
    <origin xyz="-0.0773912 0.102168 -0.0438135" rpy="-1.5708 6.02296e-15 -1.5708"/>
    <parent link="hipsubasm"/>
    <child link="toplegasm_4"/>
    <axis xyz="0 0 1"/>
    <limit effort="10" velocity="10" lower="-1.5708" upper="1.5708"/>
  </joint>
</robot>
